test/order-book-sample.json
{
  "orders": [
    {
      "id": "7e7c0b6c-1d32-4d15-b366-ccbc46024e40",
      "quantity": 10,
      "price": 2,
      "executedQuantity": 0,
      "isBuyOrder": true,
      "executedOrders": []
    },
    {
      "id": "fbe6613d-d739-4882-99c3-9f578a051ffd",
      "quantity": 5,
      "price": 3,
      "executedQuantity": 0,
      "isBuyOrder": true,
      "executedOrders": []
    },
    {
      "id": "297dd8db-4aee-4ff1-aa25-88e1b08885a4",
      "quantity": 50,
      "price": 8,
      "executedQuantity": 50,
      "isBuyOrder": false,
      "executedOrders": [
        "b1be6d95-c251-4e58-b6bd-8b01e781b1f1"
      ]
    },
    {
      "id": "eb56818f-eb93-4e70-9325-ee958e5029b7",
      "quantity": 5,
      "price": 12,
      "executedQuantity": 5,
      "isBuyOrder": false,
      "executedOrders": [
        "7d4795b4-6ee3-4197-b5ba-acc038683aee"
      ]
    },
    {
      "id": "b1be6d95-c251-4e58-b6bd-8b01e781b1f1",
      "quantity": 51,
      "price": 9,
      "executedQuantity": 51,
      "isBuyOrder": true,
      "executedOrders": [
        "297dd8db-4aee-4ff1-aa25-88e1b08885a4",
        "5ef5c586-a23a-4029-825f-8fd2495cd7c2"
      ]
    },
    {
      "id": "ae17186a-0438-4785-ba26-cef657598fb6",
      "quantity": 10,
      "price": 12,
      "executedQuantity": 10,
      "isBuyOrder": false,
      "executedOrders": [
        "7d4795b4-6ee3-4197-b5ba-acc038683aee"
      ]
    },
    {
      "id": "a2b9f338-aa49-402d-8d96-6c428dcd8ec3",
      "quantity": 1,
      "price": 12,
      "executedQuantity": 0,
      "isBuyOrder": false,
      "executedOrders": []
    },
    {
      "id": "5f2bc97a-61fe-45d6-b7f4-eb39418faea1",
      "quantity": 2,
      "price": 12,
      "executedQuantity": 0,
      "isBuyOrder": false,
      "executedOrders": []
    },
    {
      "id": "7d4795b4-6ee3-4197-b5ba-acc038683aee",
      "quantity": 15,
      "price": 13,
      "executedQuantity": 15,
      "isBuyOrder": true,
      "executedOrders": [
        "eb56818f-eb93-4e70-9325-ee958e5029b7",
        "ae17186a-0438-4785-ba26-cef657598fb6"
      ]
    },
    {
      "id": "5ef5c586-a23a-4029-825f-8fd2495cd7c2",
      "quantity": 40,
      "price": 4,
      "executedQuantity": 34,
      "isBuyOrder": false,
      "executedOrders": [
        "b1be6d95-c251-4e58-b6bd-8b01e781b1f1",
        "df2a6983-a1c4-4634-8283-d53fb9ac7bfb",
        "cacaf5dd-fd92-4910-8b77-1c2cacf06b7a",
        "20a8ee4b-c9b8-42f6-a00e-87e192f5c9fc",
        "bc215d9d-6989-411f-8932-27e8faa38691"
      ]
    },
    {
      "id": "18e48528-743f-412d-99e6-4150d193ed8b",
      "quantity": 10,
      "price": 4,
      "executedQuantity": 0,
      "isBuyOrder": false,
      "executedOrders": []
    },
    {
      "id": "cc1e0e24-a771-4df4-a91f-814fe71ed1ba",
      "quantity": 10,
      "price": 6,
      "executedQuantity": 0,
      "isBuyOrder": false,
      "executedOrders": []
    },
    {
      "id": "df2a6983-a1c4-4634-8283-d53fb9ac7bfb",
      "quantity": 10,
      "price": 4,
      "executedQuantity": 10,
      "isBuyOrder": true,
      "executedOrders": [
        "5ef5c586-a23a-4029-825f-8fd2495cd7c2"
      ]
    },
    {
      "id": "cacaf5dd-fd92-4910-8b77-1c2cacf06b7a",
      "quantity": 10,
      "price": 5,
      "executedQuantity": 10,
      "isBuyOrder": true,
      "executedOrders": [
        "5ef5c586-a23a-4029-825f-8fd2495cd7c2"
      ]
    },
    {
      "id": "20a8ee4b-c9b8-42f6-a00e-87e192f5c9fc",
      "quantity": 10,
      "price": 7,
      "executedQuantity": 10,
      "isBuyOrder": true,
      "executedOrders": [
        "5ef5c586-a23a-4029-825f-8fd2495cd7c2"
      ]
    },
    {
      "id": "bc215d9d-6989-411f-8932-27e8faa38691",
      "quantity": 3,
      "price": 4,
      "executedQuantity": 3,
      "isBuyOrder": true,
      "executedOrders": [
        "5ef5c586-a23a-4029-825f-8fd2495cd7c2"
      ]
    }
  ]
}
